require 'pry'

class AuthenticationError < StandardError; end

# A mock search engine
# that returns a random number instead of an actual count.
class SearchEngine
  def self.count(query, api_key)
    unless valid?(api_key)
      raise AuthenticationError, 'API key is not valid.'
    end

    rand(200_000)
  end

  private

  def self.valid?(key)
    key == 'LS1A'
  end
end

module DoesItRock
  # API_KEY = 'LS1A'
  API_KEY = 'TEST'

  class NoScore; end

  class Score
    def self.for_term(term)
      positive = SearchEngine.count(%{"#{term} rocks"}, API_KEY).to_f
      negative = SearchEngine.count(%{"#{term} is not fun"}, API_KEY).to_f

      positive / (positive + negative)
    rescue ZeroDivisionError
      NoScore.new
    end
  end

  def self.find_out(term)
    score = Score.for_term(term)

    binding.pry
    case score
    when NoScore
      "No idea about #{term}..."
    when 0...0.5
      "#{term} is not fun."
    when 0.5
      "#{term} seems to be ok..."
    else
      "#{term} rocks!"
    end
  rescue AuthenticationError => e
    e.message
  end
end

# Example (your output may differ)

puts DoesItRock.find_out('Sushi')       # Sushi seems to be ok...
puts DoesItRock.find_out('Rain')        # Rain is not fun.
puts DoesItRock.find_out('Bug hunting') # Bug hunting rocks!

=begin
Changing the API Key did not break the program/modify output.

The exception was raised, but handled by the `rescue` statement in the `for_term` method. A NoScore object is returned, but it's not handled correctly by the `case` statement.
=end
